<mujoco model="spider_robot"><actuator><motor name="leg1_upper_joint_motor" joint="leg1_upper_joint" gear="300" /><motor name="leg5_upper_joint_motor" joint="leg5_upper_joint" gear="300" /><motor name="leg9_upper_joint_motor" joint="leg9_upper_joint" gear="300" /><motor name="leg13_upper_joint_motor" joint="leg13_upper_joint" gear="300" /><motor name="leg1_lower_joint_motor" joint="leg1_lower_joint" gear="300" /><motor name="leg5_lower_joint_motor" joint="leg5_lower_joint" gear="300" /><motor name="leg9_lower_joint_motor" joint="leg9_lower_joint" gear="300" /><motor name="leg13_lower_joint_motor" joint="leg13_lower_joint" gear="300" /><motor name="leg2_upper_joint_motor" joint="leg2_upper_joint" gear="300" /><motor name="leg6_upper_joint_motor" joint="leg6_upper_joint" gear="300" /><motor name="leg10_upper_joint_motor" joint="leg10_upper_joint" gear="300" /><motor name="leg14_upper_joint_motor" joint="leg14_upper_joint" gear="300" /><motor name="leg2_lower_joint_motor" joint="leg2_lower_joint" gear="300" /><motor name="leg6_lower_joint_motor" joint="leg6_lower_joint" gear="300" /><motor name="leg10_lower_joint_motor" joint="leg10_lower_joint" gear="300" /><motor name="leg14_lower_joint_motor" joint="leg14_lower_joint" gear="300" /><motor name="leg3_upper_joint_motor" joint="leg3_upper_joint" gear="300" /><motor name="leg7_upper_joint_motor" joint="leg7_upper_joint" gear="300" /><motor name="leg11_upper_joint_motor" joint="leg11_upper_joint" gear="300" /><motor name="leg15_upper_joint_motor" joint="leg15_upper_joint" gear="300" /><motor name="leg3_lower_joint_motor" joint="leg3_lower_joint" gear="300" /><motor name="leg7_lower_joint_motor" joint="leg7_lower_joint" gear="300" /><motor name="leg11_lower_joint_motor" joint="leg11_lower_joint" gear="300" /><motor name="leg15_lower_joint_motor" joint="leg15_lower_joint" gear="300" /><motor name="leg4_upper_joint_motor" joint="leg4_upper_joint" gear="300" /><motor name="leg8_upper_joint_motor" joint="leg8_upper_joint" gear="300" /><motor name="leg12_upper_joint_motor" joint="leg12_upper_joint" gear="300" /><motor name="leg16_upper_joint_motor" joint="leg16_upper_joint" gear="300" /><motor name="leg4_lower_joint_motor" joint="leg4_lower_joint" gear="300" /><motor name="leg8_lower_joint_motor" joint="leg8_lower_joint" gear="300" /><motor name="leg12_lower_joint_motor" joint="leg12_lower_joint" gear="300" /><motor name="leg16_lower_joint_motor" joint="leg16_lower_joint" gear="300" /></actuator><option gravity="0 0 -9.81" /><worldbody><light diffuse=".5 .5 .5" pos="0 0 6" dir="0 0 -2" /><geom type="plane" size="5 5 0.1" rgba=".9 .9 .9 1" mass="1" /><body name="main" pos="0 0 1.5"><joint type="free" /><geom type="sphere" size="0.2" rgba="0.486 0.917 0.97 0.75" /><body name="leg1_upper_leg" pos="0.4 0 0"><joint name="leg1_upper_joint" type="hinge" pos="-0.2 0 0" axis="0 1 0" range="-15 0" damping="0.1" /><geom type="cylinder" size="0.05 0.2" rgba="1 0 0 1" euler="0 90 0" mass="2" /><body name="leg5_upper_leg" pos="0.4 0 0"><joint name="leg5_upper_joint" type="hinge" pos="-0.2 0 0" axis="0 1 0" range="-15 0" damping="0.1" /><geom type="cylinder" size="0.05 0.2" rgba="1 0 0 1" euler="0 90 0" mass="2" /><body name="leg9_upper_leg" pos="0.4 0 0"><joint name="leg9_upper_joint" type="hinge" pos="-0.2 0 0" axis="0 1 0" range="-15 0" damping="0.1" /><geom type="cylinder" size="0.05 0.2" rgba="1 0 0 1" euler="0 90 0" mass="2" /><body name="leg13_upper_leg" pos="0.4 0 0"><joint name="leg13_upper_joint" type="hinge" pos="-0.2 0 0" axis="0 1 0" range="-15 0" damping="0.1" /><geom type="cylinder" size="0.05 0.2" rgba="1 0 0 1" euler="0 90 0" mass="2" /><body name="leg1_lower_leg" pos="0.2 0 -0.2"><joint name="leg1_lower_joint" type="hinge" pos="0 0 0.2" axis="0 1 0" range="0 30" damping="0.1" /><geom type="cylinder" pos="0 0 0" size="0.04 0.2" rgba="0.486 0.917 0.97 0.75" mass="10" /><body name="leg5_lower_leg" pos="0 0 -0.4"><joint name="leg5_lower_joint" type="hinge" pos="0 0 0.2" axis="0 1 0" range="0 30" damping="0.1" /><geom type="cylinder" pos="0 0 0" size="0.04 0.2" rgba="0.486 0.917 0.97 0.75" mass="10" /><body name="leg9_lower_leg" pos="0 0 -0.4"><joint name="leg9_lower_joint" type="hinge" pos="0 0 0.2" axis="0 1 0" range="0 30" damping="0.1" /><geom type="cylinder" pos="0 0 0" size="0.04 0.2" rgba="0.486 0.917 0.97 0.75" mass="10" /><body name="leg13_lower_leg" pos="0 0 -0.4"><joint name="leg13_lower_joint" type="hinge" pos="0 0 0.2" axis="0 1 0" range="0 30" damping="0.1" /><geom type="cylinder" pos="0 0 0" size="0.04 0.2" rgba="0.486 0.917 0.97 0.75" mass="10" /></body></body></body></body></body></body></body></body><body name="leg2_upper_leg" pos="0 0.4 0"><joint name="leg2_upper_joint" type="hinge" pos="0 -0.2 0" axis="1 0 0" range="0 15" damping="0.1" /><geom type="cylinder" size="0.05 0.2" rgba="0 1 0 1" euler="90 0 0" mass="2" /><body name="leg6_upper_leg" pos="0 0.4 0"><joint name="leg6_upper_joint" type="hinge" pos="0 -0.2 0" axis="1 0 0" range="0 15" damping="0.1" /><geom type="cylinder" size="0.05 0.2" rgba="0 1 0 1" euler="90 0 0" mass="2" /><body name="leg10_upper_leg" pos="0 0.4 0"><joint name="leg10_upper_joint" type="hinge" pos="0 -0.2 0" axis="1 0 0" range="0 15" damping="0.1" /><geom type="cylinder" size="0.05 0.2" rgba="0 1 0 1" euler="90 0 0" mass="2" /><body name="leg14_upper_leg" pos="0 0.4 0"><joint name="leg14_upper_joint" type="hinge" pos="0 -0.2 0" axis="1 0 0" range="0 15" damping="0.1" /><geom type="cylinder" size="0.05 0.2" rgba="0 1 0 1" euler="90 0 0" mass="2" /><body name="leg2_lower_leg" pos="0 0.2 -0.2"><joint name="leg2_lower_joint" type="hinge" pos="0 0 0.2" axis="1 0 0" range="-30 0" damping="0.1" /><geom type="cylinder" pos="0 0 0" size="0.04 0.2" rgba="0.486 0.917 0.97 0.75" mass="10" /><body name="leg6_lower_leg" pos="0 0 -0.4"><joint name="leg6_lower_joint" type="hinge" pos="0 0 0.2" axis="1 0 0" range="-30 0" damping="0.1" /><geom type="cylinder" pos="0 0 0" size="0.04 0.2" rgba="0.486 0.917 0.97 0.75" mass="10" /><body name="leg10_lower_leg" pos="0 0 -0.4"><joint name="leg10_lower_joint" type="hinge" pos="0 0 0.2" axis="1 0 0" range="-30 0" damping="0.1" /><geom type="cylinder" pos="0 0 0" size="0.04 0.2" rgba="0.486 0.917 0.97 0.75" mass="10" /><body name="leg14_lower_leg" pos="0 0 -0.4"><joint name="leg14_lower_joint" type="hinge" pos="0 0 0.2" axis="1 0 0" range="-30 0" damping="0.1" /><geom type="cylinder" pos="0 0 0" size="0.04 0.2" rgba="0.486 0.917 0.97 0.75" mass="10" /></body></body></body></body></body></body></body></body><body name="leg3_upper_leg" pos="-0.4 0 0"><joint name="leg3_upper_joint" type="hinge" pos="0.2 0 0" axis="0 1 0" range="0 15" damping="0.1" /><geom type="cylinder" size="0.05 0.2" rgba="0 0 1 1" euler="0 -90 0" mass="2" /><body name="leg7_upper_leg" pos="-0.4 0 0"><joint name="leg7_upper_joint" type="hinge" pos="0.2 0 0" axis="0 1 0" range="0 15" damping="0.1" /><geom type="cylinder" size="0.05 0.2" rgba="0 0 1 1" euler="0 -90 0" mass="2" /><body name="leg11_upper_leg" pos="-0.4 0 0"><joint name="leg11_upper_joint" type="hinge" pos="0.2 0 0" axis="0 1 0" range="0 15" damping="0.1" /><geom type="cylinder" size="0.05 0.2" rgba="0 0 1 1" euler="0 -90 0" mass="2" /><body name="leg15_upper_leg" pos="-0.4 0 0"><joint name="leg15_upper_joint" type="hinge" pos="0.2 0 0" axis="0 1 0" range="0 15" damping="0.1" /><geom type="cylinder" size="0.05 0.2" rgba="0 0 1 1" euler="0 -90 0" mass="2" /><body name="leg3_lower_leg" pos="-0.2 0 -0.2"><joint name="leg3_lower_joint" type="hinge" pos="0 0 0.2" axis="0 1 0" range="-30 0" damping="0.1" /><geom type="cylinder" pos="0 0 0" size="0.04 0.2" rgba="0.486 0.917 0.97 0.75" mass="10" /><body name="leg7_lower_leg" pos="0 0 -0.4"><joint name="leg7_lower_joint" type="hinge" pos="0 0 0.2" axis="0 1 0" range="-30 0" damping="0.1" /><geom type="cylinder" pos="0 0 0" size="0.04 0.2" rgba="0.486 0.917 0.97 0.75" mass="10" /><body name="leg11_lower_leg" pos="0 0 -0.4"><joint name="leg11_lower_joint" type="hinge" pos="0 0 0.2" axis="0 1 0" range="-30 0" damping="0.1" /><geom type="cylinder" pos="0 0 0" size="0.04 0.2" rgba="0.486 0.917 0.97 0.75" mass="10" /><body name="leg15_lower_leg" pos="0 0 -0.4"><joint name="leg15_lower_joint" type="hinge" pos="0 0 0.2" axis="0 1 0" range="-30 0" damping="0.1" /><geom type="cylinder" pos="0 0 0" size="0.04 0.2" rgba="0.486 0.917 0.97 0.75" mass="10" /></body></body></body></body></body></body></body></body><body name="leg4_upper_leg" pos="0 -0.4 0"><joint name="leg4_upper_joint" type="hinge" pos="0 0.2 0" axis="1 0 0" range="-15 0" damping="0.1" /><geom type="cylinder" size="0.05 0.2" rgba="0.5 0.5 0.5 1" euler="-90 0 0" mass="2" /><body name="leg8_upper_leg" pos="0 -0.4 0"><joint name="leg8_upper_joint" type="hinge" pos="0 0.2 0" axis="1 0 0" range="-15 0" damping="0.1" /><geom type="cylinder" size="0.05 0.2" rgba="0.5 0.5 0.5 1" euler="-90 0 0" mass="2" /><body name="leg12_upper_leg" pos="0 -0.4 0"><joint name="leg12_upper_joint" type="hinge" pos="0 0.2 0" axis="1 0 0" range="-15 0" damping="0.1" /><geom type="cylinder" size="0.05 0.2" rgba="0.5 0.5 0.5 1" euler="-90 0 0" mass="2" /><body name="leg16_upper_leg" pos="0 -0.4 0"><joint name="leg16_upper_joint" type="hinge" pos="0 0.2 0" axis="1 0 0" range="-15 0" damping="0.1" /><geom type="cylinder" size="0.05 0.2" rgba="0.5 0.5 0.5 1" euler="-90 0 0" mass="2" /><body name="leg4_lower_leg" pos="0 -0.2 -0.2"><joint name="leg4_lower_joint" type="hinge" pos="0 0 0.2" axis="1 0 0" range="0 30" damping="0.1" /><geom type="cylinder" pos="0 0 0" size="0.04 0.2" rgba="0.486 0.917 0.97 0.75" mass="10" /><body name="leg8_lower_leg" pos="0 0 -0.4"><joint name="leg8_lower_joint" type="hinge" pos="0 0 0.2" axis="1 0 0" range="0 30" damping="0.1" /><geom type="cylinder" pos="0 0 0" size="0.04 0.2" rgba="0.486 0.917 0.97 0.75" mass="10" /><body name="leg12_lower_leg" pos="0 0 -0.4"><joint name="leg12_lower_joint" type="hinge" pos="0 0 0.2" axis="1 0 0" range="0 30" damping="0.1" /><geom type="cylinder" pos="0 0 0" size="0.04 0.2" rgba="0.486 0.917 0.97 0.75" mass="10" /><body name="leg16_lower_leg" pos="0 0 -0.4"><joint name="leg16_lower_joint" type="hinge" pos="0 0 0.2" axis="1 0 0" range="0 30" damping="0.1" /><geom type="cylinder" pos="0 0 0" size="0.04 0.2" rgba="0.486 0.917 0.97 0.75" mass="10" /></body></body></body></body></body></body></body></body></body></worldbody></mujoco>